# 1. 问题

```text
{'loss': 2.9043, 'learning_rate': 4.999641867738336e-05, 'epoch': 0.02}
1%|▍ | 10/1856 [04:16<13:02:24, 25.43s/it][INFO|trainer.py:2926] 2023-10-19 09:48:54,430 >> Saving model checkpoint to pt_output/chatglm_pt_checkpoint_deepspeed/checkpoint-10
[INFO|configuration_utils.py:458] 2023-10-19 09:48:55,234 >> Configuration saved in pt_output/chatglm_pt_checkpoint_deepspeed/checkpoint-10/config.json
[INFO|configuration_utils.py:364] 2023-10-19 09:48:55,469 >> Configuration saved in pt_output/chatglm_pt_checkpoint_deepspeed/checkpoint-10/generation_config.json
[INFO|modeling_utils.py:1853] 2023-10-19 09:48:55,692 >> Model weights saved in pt_output/chatglm_pt_checkpoint_deepspeed/checkpoint-10/pytorch_model.bin
[INFO|tokenization_utils_base.py:2194] 2023-10-19 09:48:55,877 >> tokenizer config file saved in pt_output/chatglm_pt_checkpoint_deepspeed/checkpoint-10/tokenizer_config.json
[INFO|tokenization_utils_base.py:2201] 2023-10-19 09:48:55,941 >> Special tokens file saved in pt_output/chatglm_pt_checkpoint_deepspeed/checkpoint-10/special_tokens_map.json
[2023-10-19 09:49:06,331] [INFO] [logging.py:96:log_dist] [Rank 0] [Torch] Checkpoint global_step10 is about to be saved!
[2023-10-19 09:49:06,331] [INFO] [engine.py:3431:save_16bit_model] Saving model weights to pt_output/chatglm_pt_checkpoint_deepspeed/checkpoint-10/pytorch_model.bin, tag: global_step10
[2023-10-19 09:49:06,332] [INFO] [torch_checkpoint_engine.py:21:save] [Torch] Saving pt_output/chatglm_pt_checkpoint_deepspeed/checkpoint-10/pytorch_model.bin...
Traceback (most recent call last):
File "/home/ma-user/anaconda3/envs/myenv/lib/python3.9/site-packages/torch/serialization.py", line 423, in save
_save(obj, opened_zipfile, pickle_module, pickle_protocol)
File "/home/ma-user/anaconda3/envs/myenv/lib/python3.9/site-packages/torch/serialization.py", line 650, in _save
zip_file.write_record(name, storage.data_ptr(), num_bytes)
RuntimeError: [enforce fail at inline_container.cc:445] . PytorchStreamWriter failed writing file data/176: file write failed

During handling of the above exception, another exception occurred:

Traceback (most recent call last):
File "/data/chatglm/LLaMA-Efficient-Tuning-main/src/train_bash.py", line 16, in
main()
File "/data/chatglm/LLaMA-Efficient-Tuning-main/src/train_bash.py", line 7, in main
run_exp()
File "/data/chatglm/LLaMA-Efficient-Tuning-main/src/llmtuner/tuner/tune.py", line 25, in run_exp
run_pt(model_args, data_args, training_args, finetuning_args, callbacks)
File "/data/chatglm/LLaMA-Efficient-Tuning-main/src/llmtuner/tuner/pt/workflow.py", line 40, in run_pt
train_result = trainer.train(resume_from_checkpoint=training_args.resume_from_checkpoint)
File "/home/ma-user/anaconda3/envs/myenv/lib/python3.9/site-packages/transformers/trainer.py", line 1645, in train
return inner_training_loop(
File "/home/ma-user/anaconda3/envs/myenv/lib/python3.9/site-packages/transformers/trainer.py", line 2020, in _inner_training_loop
self._maybe_log_save_evaluate(tr_loss, model, trial, epoch, ignore_keys_for_eval)
File "/home/ma-user/anaconda3/envs/myenv/lib/python3.9/site-packages/transformers/trainer.py", line 2332, in _maybe_log_save_evaluate
self._save_checkpoint(model, trial, metrics=metrics)
File "/home/ma-user/anaconda3/envs/myenv/lib/python3.9/site-packages/transformers/trainer.py", line 2389, in _save_checkpoint
self.save_model(output_dir, _internal_call=True)
File "/home/ma-user/anaconda3/envs/myenv/lib/python3.9/site-packages/transformers/trainer.py", line 2879, in save_model
if not self.model_wrapped.save_16bit_model(output_dir, WEIGHTS_NAME):
File "/home/ma-user/anaconda3/envs/myenv/lib/python3.9/site-packages/deepspeed/runtime/engine.py", line 3432, in save_16bit_model
self.checkpoint_engine.save(state_dict, path)
File "/home/ma-user/anaconda3/envs/myenv/lib/python3.9/site-packages/deepspeed/runtime/checkpoint_engine/torch_checkpoint_engine.py", line 22, in save
torch.save(state_dict, path)
File "/home/ma-user/anaconda3/envs/myenv/lib/python3.9/site-packages/torch/serialization.py", line 424, in save
return
File "/home/ma-user/anaconda3/envs/myenv/lib/python3.9/site-packages/torch/serialization.py", line 290, in exit
self.file_like.write_end_of_file()
RuntimeError: [enforce fail at inline_container.cc:325] . unexpected pos 10706615232 vs 10706615128
```

# 2. 解决方案

这个错误是项目所在的硬盘空间满了，导致无法保存ckpt后报错。我也遇到了，清理磁盘后已解决。


# 参考

[1] 保存权重时报错 #1223, https://github.com/hiyouga/LLaMA-Factory/issues/1223
